Workbook

Sheet Leia-me
A1: Planilha de conferência - SPEC Calibra
A3: Objetivo: conferir as fórmulas da SPEC (seção 7.1) e os casos golden (7.6) antes de escrever o calibra-core.
A4: Amarelo = entrada; azul = cálculo (não editar); verde = conferência.
A5: Abas: Cadeia (fórmulas, colunas = golden A a D), Iteracao (MAP-Tm), Combustiveis (SPEC 7.2), Conferencia (esperado x calculado, 1%).
A6: Golden B usa 2.000 cc (a spec não dá o diâmetro). Golden A usa o caminho por BSFC; B, C e D usam k_ar. Ver docs/decisoes.md.
A7: Esta planilha é gerada por gerar-planilha.ps1. Para mudar de verdade, editar o script e gerar de novo.

Sheet Cadeia
A1: Cadeia de cálculo - fórmulas da SPEC 7.1
A2: Colunas C a F = casos golden A a D da SPEC 7.6. Amarelo = entrada; azul = cálculo. A iteração MAP-Tm está na aba Iteracao; a conferência de 1% na aba Conferencia.
A3: Item | B3: Unidade | C3: A Garrett | D3: B 2.0 turbo EHC | E3: C 1.0 3 cil E32 | F3: D V12 aspirado E32 | G3: Observação
A4: ENTRADAS
A5: Potência no virabrequim | B5: cv | C5: =650/0.98632 | D5: 400 | E5: 150 | F5: 450 | G5: A: 650 hp
A6: Caminho da vazão de ar | B6: - | C6: BSFC | D6: K_AR | E6: K_AR | F6: K_AR | G6: K_AR = padrão; BSFC = opcional (decisão 8)
A7: k_ar | B7: hp por lb/min | C7: 10.5 | D7: 10.5 | E7: 10.5 | F7: 10.5
A8: A/F (caminho BSFC) | B8: :1 | C8: 11.5
A9: BSFC (caminho BSFC) | B9: lb/hp·h | C9: 0.46
A10: AFR estequiométrico | B10: :1 | D10: =Combustiveis!D13 | E10: =Combustiveis!D11 | F10: =Combustiveis!D11
A11: Lambda alvo | B11: λ | D11: 0.8 | E11: 0.8 | F11: 0.87
A12: Cilindros (1 bico por cilindro) | B12: - | D12: 4 | E12: 3 | F12: 12
A13: Diâmetro | B13: mm | D13: =SQRT(2000*1000/(PI()/4*92.8*4)) | E13: 74.5 | F13: 89 | G13: B: diâmetro que dá 2.000 cc (decisão 7)
A14: Curso | B14: mm | D14: 92.8 | E14: 76.4 | F14: 80.4
A15: Cilindrada informada (só A) | B15: pol³ | C15: 348
A16: Rotação | B16: rpm | C16: 6000 | D16: 7000 | E16: 5500 | F16: 6500
A17: VE | B17: - | C17: 0.8 | D17: 0.95 | E17: 0.95 | F17: 0.9
A18: Sobrealimentação | B18: - | C18: FIXO | D18: SIM | E18: SIM | F18: NAO | G18: FIXO = Tm informado (exemplo Garrett)
A19: Tm fixo (só A) | B19: °C | C19: =(130-32)*5/9 | G19: 130 °F
A20: Temperatura ambiente | B20: °C | D20: 25 | E20: 25 | F20: 25
A21: Altitude | B21: m | C21: 0 | D21: 600 | E21: 600 | F21: 600
A22: Perda depois do compressor | B22: psi | C22: 2 | D22: 2 | E22: 2 | F22: 2
A23: Perda antes do compressor | B23: psi | C23: 1 | D23: 1 | E23: 1 | F23: 1
A24: eta_c | B24: - | D24: 0.72 | E24: 0.72
A25: eps do intercooler | B25: - | D25: 0.8 | E25: 0.8
A26: Acréscimo de Tm no aspirado | B26: °C | F26: 10
A27: DC máximo | B27: - | D27: 0.8 | E27: 0.8 | F27: 0.8
A28: Densidade do combustível | B28: kg/L | D28: =Combustiveis!E13 | E28: =Combustiveis!E11 | F28: =Combustiveis!E11
A29: Densidade do fluido de teste | B29: kg/L | D29: 0.7 | E29: 0.7 | F29: 0.7
A30: Bico nominal | B30: cc/min | D30: 1050 | E30: 440 | F30: 260
A31: Pressão de teste do bico | B31: bar | D31: 3 | E31: 3 | F31: 3
A32: Pressão de trabalho (diferencial) | B32: bar | D32: 3 | E32: 3 | F32: 3
A33: Tempo morto | B33: ms | D33: 1 | E33: 1 | F33: 1
A34: Bico alternativo 1 | B34: cc/min | D34: 1300
A35: Pressão do alternativo 1 | B35: bar | D35: 3
A36: Bico alternativo 2 | B36: cc/min | D36: 1050
A37: Pressão do alternativo 2 | B37: bar | D37: 4
A38: CÁLCULOS
A39: Potência | B39: hp | C39: =C5*0.98632 | D39: =D5*0.98632 | E39: =E5*0.98632 | F39: =F5*0.98632
A40: Potência | B40: kW | C40: =C5*0.7355 | D40: =D5*0.7355 | E40: =E5*0.7355 | F40: =F5*0.7355
...

Sheet Iteracao
A1: Iteração MAP - Tm (SPEC 7.1)
A2: Começa em Tm = 50 °C (sobrealimentado). Para FIXO e NAO, Tm não muda. Critério: |ΔTm| < 0,01 °C.
A3: k | B3: Tm °C (A) | C3: MAP psia (A) | D3: PR (A) | E3: T2 °C (A) | F3: Tm °C (B) | G3: MAP psia (B) | H3: PR (B) | I3: T2 °C (B) | J3: Tm °C (C) | K3: MAP psia (C) | L3: PR (C) | M3: T2 °C (C) | N3: Tm °C (D) | O3: MAP psia (D) | P3: PR (D) | Q3: T2 °C (D)
A4: 0 | B4: =Cadeia!C49 | C4: =Cadeia!C41*639.6*(460+(B4*9/5+32))/(Cadeia!C17*Cadeia!C16/2*Cadeia!C46) | D4: =(C4+Cadeia!C22)/(Cadeia!C48-Cadeia!C23) | E4: =IF(Cadeia!C18="SIM",(Cadeia!C20+273.15)*(1+(D4^0.2857-1)/Cadeia!C24)-273.15,"") | F4: =Cadeia!D49 | G4: =Cadeia!D41*639.6*(460+(F4*9/5+32))/(Cadeia!D17*Cadeia!D16/2*Cadeia!D46) | H4: =(G4+Cadeia!D22)/(Cadeia!D48-Cadeia!D23) | I4: =IF(Cadeia!D18="SIM",(Cadeia!D20+273.15)*(1+(H4^0.2857-1)/Cadeia!D24)-273.15,"") | J4: =Cadeia!E49 | K4: =Cadeia!E41*639.6*(460+(J4*9/5+32))/(Cadeia!E17*Cadeia!E16/2*Cadeia!E46) | L4: =(K4+Cadeia!E22)/(Cadeia!E48-Cadeia!E23) | M4: =IF(Cadeia!E18="SIM",(Cadeia!E20+273.15)*(1+(L4^0.2857-1)/Cadeia!E24)-273.15,"") | N4: =Cadeia!F49 | O4: =Cadeia!F41*639.6*(460+(N4*9/5+32))/(Cadeia!F17*Cadeia!F16/2*Cadeia!F46) | P4: =(O4+Cadeia!F22)/(Cadeia!F48-Cadeia!F23) | Q4: =IF(Cadeia!F18="SIM",(Cadeia!F20+273.15)*(1+(P4^0.2857-1)/Cadeia!F24)-273.15,"")
A5: 1 | B5: =IF(Cadeia!C18="SIM",E4-Cadeia!C25*(E4-Cadeia!C20),B4) | C5: =Cadeia!C41*639.6*(460+(B5*9/5+32))/(Cadeia!C17*Cadeia!C16/2*Cadeia!C46) | D5: =(C5+Cadeia!C22)/(Cadeia!C48-Cadeia!C23) | E5: =IF(Cadeia!C18="SIM",(Cadeia!C20+273.15)*(1+(D5^0.2857-1)/Cadeia!C24)-273.15,"") | F5: =IF(Cadeia!D18="SIM",I4-Cadeia!D25*(I4-Cadeia!D20),F4) | G5: =Cadeia!D41*639.6*(460+(F5*9/5+32))/(Cadeia!D17*Cadeia!D16/2*Cadeia!D46) | H5: =(G5+Cadeia!D22)/(Cadeia!D48-Cadeia!D23) | I5: =IF(Cadeia!D18="SIM",(Cadeia!D20+273.15)*(1+(H5^0.2857-1)/Cadeia!D24)-273.15,"") | J5: =IF(Cadeia!E18="SIM",M4-Cadeia!E25*(M4-Cadeia!E20),J4) | K5: =Cadeia!E41*639.6*(460+(J5*9/5+32))/(Cadeia!E17*Cadeia!E16/2*Cadeia!E46) | L5: =(K5+Cadeia!E22)/(Cadeia!E48-Cadeia!E23) | M5: =IF(Cadeia!E18="SIM",(Cadeia!E20+273.15)*(1+(L5^0.2857-1)/Cadeia!E24)-273.15,"") | N5: =IF(Cadeia!F18="SIM",Q4-Cadeia!F25*(Q4-Cadeia!F20),N4) | O5: =Cadeia!F41*639.6*(460+(N5*9/5+32))/(Cadeia!F17*Cadeia!F16/2*Cadeia!F46) | P5: =(O5+Cadeia!F22)/(Cadeia!F48-Cadeia!F23) | Q5: =IF(Cadeia!F18="SIM",(Cadeia!F20+273.15)*(1+(P5^0.2857-1)/Cadeia!F24)-273.15,"")
A6: 2 | B6: =IF(Cadeia!C18="SIM",E5-Cadeia!C25*(E5-Cadeia!C20),B5) | C6: =Cadeia!C41*639.6*(460+(B6*9/5+32))/(Cadeia!C17*Cadeia!C16/2*Cadeia!C46) | D6: =(C6+Cadeia!C22)/(Cadeia!C48-Cadeia!C23) | E6: =IF(Cadeia!C18="SIM",(Cadeia!C20+273.15)*(1+(D6^0.2857-1)/Cadeia!C24)-273.15,"") | F6: =IF(Cadeia!D18="SIM",I5-Cadeia!D25*(I5-Cadeia!D20),F5) | G6: =Cadeia!D41*639.6*(460+(F6*9/5+32))/(Cadeia!D17*Cadeia!D16/2*Cadeia!D46) | H6: =(G6+Cadeia!D22)/(Cadeia!D48-Cadeia!D23) | I6: =IF(Cadeia!D18="SIM",(Cadeia!D20+273.15)*(1+(H6^0.2857-1)/Cadeia!D24)-273.15,"") | J6: =IF(Cadeia!E18="SIM",M5-Cadeia!E25*(M5-Cadeia!E20),J5) | K6: =Cadeia!E41*639.6*(460+(J6*9/5+32))/(Cadeia!E17*Cadeia!E16/2*Cadeia!E46) | L6: =(K6+Cadeia!E22)/(Cadeia!E48-Cadeia!E23) | M6: =IF(Cadeia!E18="SIM",(Cadeia!E20+273.15)*(1+(L6^0.2857-1)/Cadeia!E24)-273.15,"") | N6: =IF(Cadeia!F18="SIM",Q5-Cadeia!F25*(Q5-Cadeia!F20),N5) | O6: =Cadeia!F41*639.6*(460+(N6*9/5+32))/(Cadeia!F17*Cadeia!F16/2*Cadeia!F46) | P6: =(O6+Cadeia!F22)/(Cadeia!F48-Cadeia!F23) | Q6: =IF(Cadeia!F18="SIM",(Cadeia!F20+273.15)*(1+(P6^0.2857-1)/Cadeia!F24)-273.15,"")
A7: 3 | B7: =IF(Cadeia!C18="SIM",E6-Cadeia!C25*(E6-Cadeia!C20),B6) | C7: =Cadeia!C41*639.6*(460+(B7*9/5+32))/(Cadeia!C17*Cadeia!C16/2*Cadeia!C46) | D7: =(C7+Cadeia!C22)/(Cadeia!C48-Cadeia!C23) | E7: =IF(Cadeia!C18="SIM",(Cadeia!C20+273.15)*(1+(D7^0.2857-1)/Cadeia!C24)-273.15,"") | F7: =IF(Cadeia!D18="SIM",I6-Cadeia!D25*(I6-Cadeia!D20),F6) | G7: =Cadeia!D41*639.6*(460+(F7*9/5+32))/(Cadeia!D17*Cadeia!D16/2*Cadeia!D46) | H7: =(G7+Cadeia!D22)/(Cadeia!D48-Cadeia!D23) | I7: =IF(Cadeia!D18="SIM",(Cadeia!D20+273.15)*(1+(H7^0.2857-1)/Cadeia!D24)-273.15,"") | J7: =IF(Cadeia!E18="SIM",M6-Cadeia!E25*(M6-Cadeia!E20),J6) | K7: =Cadeia!E41*639.6*(460+(J7*9/5+32))/(Cadeia!E17*Cadeia!E16/2*Cadeia!E46) | L7: =(K7+Cadeia!E22)/(Cadeia!E48-Cadeia!E23) | M7: =IF(Cadeia!E18="SIM",(Cadeia!E20+273.15)*(1+(L7^0.2857-1)/Cadeia!E24)-273.15,"") | N7: =IF(Cadeia!F18="SIM",Q6-Cadeia!F25*(Q6-Cadeia!F20),N6) | O7: =Cadeia!F41*639.6*(460+(N7*9/5+32))/(Cadeia!F17*Cadeia!F16/2*Cadeia!F46) | P7: =(O7+Cadeia!F22)/(Cadeia!F48-Cadeia!F23) | Q7: =IF(Cadeia!F18="SIM",(Cadeia!F20+273.15)*(1+(P7^0.2857-1)/Cadeia!F24)-273.15,"")
A8: 4 | B8: =IF(Cadeia!C18="SIM",E7-Cadeia!C25*(E7-Cadeia!C20),B7) | C8: =Cadeia!C41*639.6*(460+(B8*9/5+32))/(Cadeia!C17*Cadeia!C16/2*Cadeia!C46) | D8: =(C8+Cadeia!C22)/(Cadeia!C48-Cadeia!C23) | E8: =IF(Cadeia!C18="SIM",(Cadeia!C20+273.15)*(1+(D8^0.2857-1)/Cadeia!C24)-273.15,"") | F8: =IF(Cadeia!D18="SIM",I7-Cadeia!D25*(I7-Cadeia!D20),F7) | G8: =Cadeia!D41*639.6*(460+(F8*9/5+32))/(Cadeia!D17*Cadeia!D16/2*Cadeia!D46) | H8: =(G8+Cadeia!D22)/(Cadeia!D48-Cadeia!D23) | I8: =IF(Cadeia!D18="SIM",(Cadeia!D20+273.15)*(1+(H8^0.2857-1)/Cadeia!D24)-273.15,"") | J8: =IF(Cadeia!E18="SIM",M7-Cadeia!E25*(M7-Cadeia!E20),J7) | K8: =Cadeia!E41*639.6*(460+(J8*9/5+32))/(Cadeia!E17*Cadeia!E16/2*Cadeia!E46) | L8: =(K8+Cadeia!E22)/(Cadeia!E48-Cadeia!E23) | M8: =IF(Cadeia!E18="SIM",(Cadeia!E20+273.15)*(1+(L8^0.2857-1)/Cadeia!E24)-273.15,"") | N8: =IF(Cadeia!F18="SIM",Q7-Cadeia!F25*(Q7-Cadeia!F20),N7) | O8: =Cadeia!F41*639.6*(460+(N8*9/5+32))/(Cadeia!F17*Cadeia!F16/2*Cadeia!F46) | P8: =(O8+Cadeia!F22)/(Cadeia!F48-Cadeia!F23) | Q8: =IF(Cadeia!F18="SIM",(Cadeia!F20+273.15)*(1+(P8^0.2857-1)/Cadeia!F24)-273.15,"")
A9: 5 | B9: =IF(Cadeia!C18="SIM",E8-Cadeia!C25*(E8-Cadeia!C20),B8) | C9: =Cadeia!C41*639.6*(460+(B9*9/5+32))/(Cadeia!C17*Cadeia!C16/2*Cadeia!C46) | D9: =(C9+Cadeia!C22)/(Cadeia!C48-Cadeia!C23) | E9: =IF(Cadeia!C18="SIM",(Cadeia!C20+273.15)*(1+(D9^0.2857-1)/Cadeia!C24)-273.15,"") | F9: =IF(Cadeia!D18="SIM",I8-Cadeia!D25*(I8-Cadeia!D20),F8) | G9: =Cadeia!D41*639.6*(460+(F9*9/5+32))/(Cadeia!D17*Cadeia!D16/2*Cadeia!D46) | H9: =(G9+Cadeia!D22)/(Cadeia!D48-Cadeia!D23) | I9: =IF(Cadeia!D18="SIM",(Cadeia!D20+273.15)*(1+(H9^0.2857-1)/Cadeia!D24)-273.15,"") | J9: =IF(Cadeia!E18="SIM",M8-Cadeia!E25*(M8-Cadeia!E20),J8) | K9: =Cadeia!E41*639.6*(460+(J9*9/5+32))/(Cadeia!E17*Cadeia!E16/2*Cadeia!E46) | L9: =(K9+Cadeia!E22)/(Cadeia!E48-Cadeia!E23) | M9: =IF(Cadeia!E18="SIM",(Cadeia!E20+273.15)*(1+(L9^0.2857-1)/Cadeia!E24)-273.15,"") | N9: =IF(Cadeia!F18="SIM",Q8-Cadeia!F25*(Q8-Cadeia!F20),N8) | O9: =Cadeia!F41*639.6*(460+(N9*9/5+32))/(Cadeia!F17*Cadeia!F16/2*Cadeia!F46) | P9: =(O9+Cadeia!F22)/(Cadeia!F48-Cadeia!F23) | Q9: =IF(Cadeia!F18="SIM",(Cadeia!F20+273.15)*(1+(P9^0.2857-1)/Cadeia!F24)-273.15,"")
A10: 6 | B10: =IF(Cadeia!C18="SIM",E9-Cadeia!C25*(E9-Cadeia!C20),B9) | C10: =Cadeia!C41*639.6*(460+(B10*9/5+32))/(Cadeia!C17*Cadeia!C16/2*Cadeia!C46) | D10: =(C10+Cadeia!C22)/(Cadeia!C48-Cadeia!C23) | E10: =IF(Cadeia!C18="SIM",(Cadeia!C20+273.15)*(1+(D10^0.2857-1)/Cadeia!C24)-273.15,"") | F10: =IF(Cadeia!D18="SIM",I9-Cadeia!D25*(I9-Cadeia!D20),F9) | G10: =Cadeia!D41*639.6*(460+(F10*9/5+32))/(Cadeia!D17*Cadeia!D16/2*Cadeia!D46) | H10: =(G10+Cadeia!D22)/(Cadeia!D48-Cadeia!D23) | I10: =IF(Cadeia!D18="SIM",(Cadeia!D20+273.15)*(1+(H10^0.2857-1)/Cadeia!D24)-273.15,"") | J10: =IF(Cadeia!E18="SIM",M9-Cadeia!E25*(M9-Cadeia!E20),J9) | K10: =Cadeia!E41*639.6*(460+(J10*9/5+32))/(Cadeia!E17*Cadeia!E16/2*Cadeia!E46) | L10: =(K10+Cadeia!E22)/(Cadeia!E48-Cadeia!E23) | M10: =IF(Cadeia!E18="SIM",(Cadeia!E20+273.15)*(1+(L10^0.2857-1)/Cadeia!E24)-273.15,"") | N10: =IF(Cadeia!F18="SIM",Q9-Cadeia!F25*(Q9-Cadeia!F20),N9) | O10: =Cadeia!F41*639.6*(460+(N10*9/5+32))/(Cadeia!F17*Cadeia!F16/2*Cadeia!F46) | P10: =(O10+Cadeia!F22)/(Cadeia!F48-Cadeia!F23) | Q10: =IF(Cadeia!F18="SIM",(Cadeia!F20+273.15)*(1+(P10^0.2857-1)/Cadeia!F24)-273.15,"")
A11: 7 | B11: =IF(Cadeia!C18="SIM",E10-Cadeia!C25*(E10-Cadeia!C20),B10) | C11: =Cadeia!C41*639.6*(460+(B11*9/5+32))/(Cadeia!C17*Cadeia!C16/2*Cadeia!C46) | D11: =(C11+Cadeia!C22)/(Cadeia!C48-Cadeia!C23) | E11: =IF(Cadeia!C18="SIM",(Cadeia!C20+273.15)*(1+(D11^0.2857-1)/Cadeia!C24)-273.15,"") | F11: =IF(Cadeia!D18="SIM",I10-Cadeia!D25*(I10-Cadeia!D20),F10) | G11: =Cadeia!D41*639.6*(460+(F11*9/5+32))/(Cadeia!D17*Cadeia!D16/2*Cadeia!D46) | H11: =(G11+Cadeia!D22)/(Cadeia!D48-Cadeia!D23) | I11: =IF(Cadeia!D18="SIM",(Cadeia!D20+273.15)*(1+(H11^0.2857-1)/Cadeia!D24)-273.15,"") | J11: =IF(Cadeia!E18="SIM",M10-Cadeia!E25*(M10-Cadeia!E20),J10) | K11: =Cadeia!E41*639.6*(460+(J11*9/5+32))/(Cadeia!E17*Cadeia!E16/2*Cadeia!E46) | L11: =(K11+Cadeia!E22)/(Cadeia!E48-Cadeia!E23) | M11: =IF(Cadeia!E18="SIM",(Cadeia!E20+273.15)*(1+(L11^0.2857-1)/Cadeia!E24)-273.15,"") | N11: =IF(Cadeia!F18="SIM",Q10-Cadeia!F25*(Q10-Cadeia!F20),N10) | O11: =Cadeia!F41*639.6*(460+(N11*9/5+32))/(Cadeia!F17*Cadeia!F16/2*Cadeia!F46) | P11: =(O11+Cadeia!F22)/(Cadeia!F48-Cadeia!F23) | Q11: =IF(Cadeia!F18="SIM",(Cadeia!F20+273.15)*(1+(P11^0.2857-1)/Cadeia!F24)-273.15,"")
A12: 8 | B12: =IF(Cadeia!C18="SIM",E11-Cadeia!C25*(E11-Cadeia!C20),B11) | C12: =Cadeia!C41*639.6*(460+(B12*9/5+32))/(Cadeia!C17*Cadeia!C16/2*Cadeia!C46) | D12: =(C12+Cadeia!C22)/(Cadeia!C48-Cadeia!C23) | E12: =IF(Cadeia!C18="SIM",(Cadeia!C20+273.15)*(1+(D12^0.2857-1)/Cadeia!C24)-273.15,"") | F12: =IF(Cadeia!D18="SIM",I11-Cadeia!D25*(I11-Cadeia!D20),F11) | G12: =Cadeia!D41*639.6*(460+(F12*9/5+32))/(Cadeia!D17*Cadeia!D16/2*Cadeia!D46) | H12: =(G12+Cadeia!D22)/(Cadeia!D48-Cadeia!D23) | I12: =IF(Cadeia!D18="SIM",(Cadeia!D20+273.15)*(1+(H12^0.2857-1)/Cadeia!D24)-273.15,"") | J12: =IF(Cadeia!E18="SIM",M11-Cadeia!E25*(M11-Cadeia!E20),J11) | K12: =Cadeia!E41*639.6*(460+(J12*9/5+32))/(Cadeia!E17*Cadeia!E16/2*Cadeia!E46) | L12: =(K12+Cadeia!E22)/(Cadeia!E48-Cadeia!E23) | M12: =IF(Cadeia!E18="SIM",(Cadeia!E20+273.15)*(1+(L12^0.2857-1)/Cadeia!E24)-273.15,"") | N12: =IF(Cadeia!F18="SIM",Q11-Cadeia!F25*(Q11-Cadeia!F20),N11) | O12: =Cadeia!F41*639.6*(460+(N12*9/5+32))/(Cadeia!F17*Cadeia!F16/2*Cadeia!F46) | P12: =(O12+Cadeia!F22)/(Cadeia!F48-Cadeia!F23) | Q12: =IF(Cadeia!F18="SIM",(Cadeia!F20+273.15)*(1+(P12^0.2857-1)/Cadeia!F24)-273.15,"")
A13: 9 | B13: =IF(Cadeia!C18="SIM",E12-Cadeia!C25*(E12-Cadeia!C20),B12) | C13: =Cadeia!C41*639.6*(460+(B13*9/5+32))/(Cadeia!C17*Cadeia!C16/2*Cadeia!C46) | D13: =(C13+Cadeia!C22)/(Cadeia!C48-Cadeia!C23) | E13: =IF(Cadeia!C18="SIM",(Cadeia!C20+273.15)*(1+(D13^0.2857-1)/Cadeia!C24)-273.15,"") | F13: =IF(Cadeia!D18="SIM",I12-Cadeia!D25*(I12-Cadeia!D20),F12) | G13: =Cadeia!D41*639.6*(460+(F13*9/5+32))/(Cadeia!D17*Cadeia!D16/2*Cadeia!D46) | H13: =(G13+Cadeia!D22)/(Cadeia!D48-Cadeia!D23) | I13: =IF(Cadeia!D18="SIM",(Cadeia!D20+273.15)*(1+(H13^0.2857-1)/Cadeia!D24)-273.15,"") | J13: =IF(Cadeia!E18="SIM",M12-Cadeia!E25*(M12-Cadeia!E20),J12) | K13: =Cadeia!E41*639.6*(460+(J13*9/5+32))/(Cadeia!E17*Cadeia!E16/2*Cadeia!E46) | L13: =(K13+Cadeia!E22)/(Cadeia!E48-Cadeia!E23) | M13: =IF(Cadeia!E18="SIM",(Cadeia!E20+273.15)*(1+(L13^0.2857-1)/Cadeia!E24)-273.15,"") | N13: =IF(Cadeia!F18="SIM",Q12-Cadeia!F25*(Q12-Cadeia!F20),N12) | O13: =Cadeia!F41*639.6*(460+(N13*9/5+32))/(Cadeia!F17*Cadeia!F16/2*Cadeia!F46) | P13: =(O13+Cadeia!F22)/(Cadeia!F48-Cadeia!F23) | Q13: =IF(Cadeia!F18="SIM",(Cadeia!F20+273.15)*(1+(P13^0.2857-1)/Cadeia!F24)-273.15,"")
A14: 10 | B14: =IF(Cadeia!C18="SIM",E13-Cadeia!C25*(E13-Cadeia!C20),B13) | C14: =Cadeia!C41*639.6*(460+(B14*9/5+32))/(Cadeia!C17*Cadeia!C16/2*Cadeia!C46) | D14: =(C14+Cadeia!C22)/(Cadeia!C48-Cadeia!C23) | E14: =IF(Cadeia!C18="SIM",(Cadeia!C20+273.15)*(1+(D14^0.2857-1)/Cadeia!C24)-273.15,"") | F14: =IF(Cadeia!D18="SIM",I13-Cadeia!D25*(I13-Cadeia!D20),F13) | G14: =Cadeia!D41*639.6*(460+(F14*9/5+32))/(Cadeia!D17*Cadeia!D16/2*Cadeia!D46) | H14: =(G14+Cadeia!D22)/(Cadeia!D48-Cadeia!D23) | I14: =IF(Cadeia!D18="SIM",(Cadeia!D20+273.15)*(1+(H14^0.2857-1)/Cadeia!D24)-273.15,"") | J14: =IF(Cadeia!E18="SIM",M13-Cadeia!E25*(M13-Cadeia!E20),J13) | K14: =Cadeia!E41*639.6*(460+(J14*9/5+32))/(Cadeia!E17*Cadeia!E16/2*Cadeia!E46) | L14: =(K14+Cadeia!E22)/(Cadeia!E48-Cadeia!E23) | M14: =IF(Cadeia!E18="SIM",(Cadeia!E20+273.15)*(1+(L14^0.2857-1)/Cadeia!E24)-273.15,"") | N14: =IF(Cadeia!F18="SIM",Q13-Cadeia!F25*(Q13-Cadeia!F20),N13) | O14: =Cadeia!F41*639.6*(460+(N14*9/5+32))/(Cadeia!F17*Cadeia!F16/2*Cadeia!F46) | P14: =(O14+Cadeia!F22)/(Cadeia!F48-Cadeia!F23) | Q14: =IF(Cadeia!F18="SIM",(Cadeia!F20+273.15)*(1+(P14^0.2857-1)/Cadeia!F24)-273.15,"")
A15: 11 | B15: =IF(Cadeia!C18="SIM",E14-Cadeia!C25*(E14-Cadeia!C20),B14) | C15: =Cadeia!C41*639.6*(460+(B15*9/5+32))/(Cadeia!C17*Cadeia!C16/2*Cadeia!C46) | D15: =(C15+Cadeia!C22)/(Cadeia!C48-Cadeia!C23) | E15: =IF(Cadeia!C18="SIM",(Cadeia!C20+273.15)*(1+(D15^0.2857-1)/Cadeia!C24)-273.15,"") | F15: =IF(Cadeia!D18="SIM",I14-Cadeia!D25*(I14-Cadeia!D20),F14) | G15: =Cadeia!D41*639.6*(460+(F15*9/5+32))/(Cadeia!D17*Cadeia!D16/2*Cadeia!D46) | H15: =(G15+Cadeia!D22)/(Cadeia!D48-Cadeia!D23) | I15: =IF(Cadeia!D18="SIM",(Cadeia!D20+273.15)*(1+(H15^0.2857-1)/Cadeia!D24)-273.15,"") | J15: =IF(Cadeia!E18="SIM",M14-Cadeia!E25*(M14-Cadeia!E20),J14) | K15: =Cadeia!E41*639.6*(460+(J15*9/5+32))/(Cadeia!E17*Cadeia!E16/2*Cadeia!E46) | L15: =(K15+Cadeia!E22)/(Cadeia!E48-Cadeia!E23) | M15: =IF(Cadeia!E18="SIM",(Cadeia!E20+273.15)*(1+(L15^0.2857-1)/Cadeia!E24)-273.15,"") | N15: =IF(Cadeia!F18="SIM",Q14-Cadeia!F25*(Q14-Cadeia!F20),N14) | O15: =Cadeia!F41*639.6*(460+(N15*9/5+32))/(Cadeia!F17*Cadeia!F16/2*Cadeia!F46) | P15: =(O15+Cadeia!F22)/(Cadeia!F48-Cadeia!F23) | Q15: =IF(Cadeia!F18="SIM",(Cadeia!F20+273.15)*(1+(P15^0.2857-1)/Cadeia!F24)-273.15,"")
A16: 12 | B16: =IF(Cadeia!C18="SIM",E15-Cadeia!C25*(E15-Cadeia!C20),B15) | C16: =Cadeia!C41*639.6*(460+(B16*9/5+32))/(Cadeia!C17*Cadeia!C16/2*Cadeia!C46) | D16: =(C16+Cadeia!C22)/(Cadeia!C48-Cadeia!C23) | E16: =IF(Cadeia!C18="SIM",(Cadeia!C20+273.15)*(1+(D16^0.2857-1)/Cadeia!C24)-273.15,"") | F16: =IF(Cadeia!D18="SIM",I15-Cadeia!D25*(I15-Cadeia!D20),F15) | G16: =Cadeia!D41*639.6*(460+(F16*9/5+32))/(Cadeia!D17*Cadeia!D16/2*Cadeia!D46) | H16: =(G16+Cadeia!D22)/(Cadeia!D48-Cadeia!D23) | I16: =IF(Cadeia!D18="SIM",(Cadeia!D20+273.15)*(1+(H16^0.2857-1)/Cadeia!D24)-273.15,"") | J16: =IF(Cadeia!E18="SIM",M15-Cadeia!E25*(M15-Cadeia!E20),J15) | K16: =Cadeia!E41*639.6*(460+(J16*9/5+32))/(Cadeia!E17*Cadeia!E16/2*Cadeia!E46) | L16: =(K16+Cadeia!E22)/(Cadeia!E48-Cadeia!E23) | M16: =IF(Cadeia!E18="SIM",(Cadeia!E20+273.15)*(1+(L16^0.2857-1)/Cadeia!E24)-273.15,"") | N16: =IF(Cadeia!F18="SIM",Q15-Cadeia!F25*(Q15-Cadeia!F20),N15) | O16: =Cadeia!F41*639.6*(460+(N16*9/5+32))/(Cadeia!F17*Cadeia!F16/2*Cadeia!F46) | P16: =(O16+Cadeia!F22)/(Cadeia!F48-Cadeia!F23) | Q16: =IF(Cadeia!F18="SIM",(Cadeia!F20+273.15)*(1+(P16^0.2857-1)/Cadeia!F24)-273.15,"")
A17: 13 | B17: =IF(Cadeia!C18="SIM",E16-Cadeia!C25*(E16-Cadeia!C20),B16) | C17: =Cadeia!C41*639.6*(460+(B17*9/5+32))/(Cadeia!C17*Cadeia!C16/2*Cadeia!C46) | D17: =(C17+Cadeia!C22)/(Cadeia!C48-Cadeia!C23) | E17: =IF(Cadeia!C18="SIM",(Cadeia!C20+273.15)*(1+(D17^0.2857-1)/Cadeia!C24)-273.15,"") | F17: =IF(Cadeia!D18="SIM",I16-Cadeia!D25*(I16-Cadeia!D20),F16) | G17: =Cadeia!D41*639.6*(460+(F17*9/5+32))/(Cadeia!D17*Cadeia!D16/2*Cadeia!D46) | H17: =(G17+Cadeia!D22)/(Cadeia!D48-Cadeia!D23) | I17: =IF(Cadeia!D18="SIM",(Cadeia!D20+273.15)*(1+(H17^0.2857-1)/Cadeia!D24)-273.15,"") | J17: =IF(Cadeia!E18="SIM",M16-Cadeia!E25*(M16-Cadeia!E20),J16) | K17: =Cadeia!E41*639.6*(460+(J17*9/5+32))/(Cadeia!E17*Cadeia!E16/2*Cadeia!E46) | L17: =(K17+Cadeia!E22)/(Cadeia!E48-Cadeia!E23) | M17: =IF(Cadeia!E18="SIM",(Cadeia!E20+273.15)*(1+(L17^0.2857-1)/Cadeia!E24)-273.15,"") | N17: =IF(Cadeia!F18="SIM",Q16-Cadeia!F25*(Q16-Cadeia!F20),N16) | O17: =Cadeia!F41*639.6*(460+(N17*9/5+32))/(Cadeia!F17*Cadeia!F16/2*Cadeia!F46) | P17: =(O17+Cadeia!F22)/(Cadeia!F48-Cadeia!F23) | Q17: =IF(Cadeia!F18="SIM",(Cadeia!F20+273.15)*(1+(P17^0.2857-1)/Cadeia!F24)-273.15,"")
A18: 14 | B18: =IF(Cadeia!C18="SIM",E17-Cadeia!C25*(E17-Cadeia!C20),B17) | C18: =Cadeia!C41*639.6*(460+(B18*9/5+32))/(Cadeia!C17*Cadeia!C16/2*Cadeia!C46) | D18: =(C18+Cadeia!C22)/(Cadeia!C48-Cadeia!C23) | E18: =IF(Cadeia!C18="SIM",(Cadeia!C20+273.15)*(1+(D18^0.2857-1)/Cadeia!C24)-273.15,"") | F18: =IF(Cadeia!D18="SIM",I17-Cadeia!D25*(I17-Cadeia!D20),F17) | G18: =Cadeia!D41*639.6*(460+(F18*9/5+32))/(Cadeia!D17*Cadeia!D16/2*Cadeia!D46) | H18: =(G18+Cadeia!D22)/(Cadeia!D48-Cadeia!D23) | I18: =IF(Cadeia!D18="SIM",(Cadeia!D20+273.15)*(1+(H18^0.2857-1)/Cadeia!D24)-273.15,"") | J18: =IF(Cadeia!E18="SIM",M17-Cadeia!E25*(M17-Cadeia!E20),J17) | K18: =Cadeia!E41*639.6*(460+(J18*9/5+32))/(Cadeia!E17*Cadeia!E16/2*Cadeia!E46) | L18: =(K18+Cadeia!E22)/(Cadeia!E48-Cadeia!E23) | M18: =IF(Cadeia!E18="SIM",(Cadeia!E20+273.15)*(1+(L18^0.2857-1)/Cadeia!E24)-273.15,"") | N18: =IF(Cadeia!F18="SIM",Q17-Cadeia!F25*(Q17-Cadeia!F20),N17) | O18: =Cadeia!F41*639.6*(460+(N18*9/5+32))/(Cadeia!F17*Cadeia!F16/2*Cadeia!F46) | P18: =(O18+Cadeia!F22)/(Cadeia!F48-Cadeia!F23) | Q18: =IF(Cadeia!F18="SIM",(Cadeia!F20+273.15)*(1+(P18^0.2857-1)/Cadeia!F24)-273.15,"")

Sheet Combustiveis
A1: Combustíveis (SPEC 7.2)
A2: Constantes da spec | B2: Valor | C2: Unidade
A3: AFR estequiométrico gasolina A | B3: 14.7 | C3: :1
A4: AFR estequiométrico etanol | B4: 9 | C4: :1
A5: Densidade gasolina A | B5: 0.74 | C5: kg/L
A6: Densidade etanol anidro | B6: 0.789 | C6: kg/L
A7: Etanol no EHC (fração em massa) | B7: 0.93 | C7: m/m
A8: Densidade EHC | B8: 0.809 | C8: kg/L
A10: Combustível | B10: Etanol (vol) | C10: Fração mássica | D10: AFR esteq. | E10: Densidade kg/L | F10: Lambda sob pressão | G10: Lambda aspirado | H10: Origem
A11: Gasolina C comum E32 | B11: 0.32 | C11: =B11*$B$6/(B11*$B$6+(1-B11)*$B$5) | D11: =(1-C11)*$B$3+C11*$B$4 | E11: =B11*$B$6+(1-B11)*$B$5 | F11: 0.8 | G11: 0.87 | H11: Calculado (vigente desde 01/08/2026)
A12: Gasolina premium E25 | B12: 0.25 | C12: =B12*$B$6/(B12*$B$6+(1-B12)*$B$5) | D12: =(1-C12)*$B$3+C12*$B$4 | E12: =B12*$B$6+(1-B12)*$B$5 | F12: 0.8 | G12: 0.87 | H12: Calculado
A13: Etanol hidratado (EHC) | B13: - | C13: =$B$7 | D13: =$B$4*$B$7 | E13: =$B$8 | F13: 0.8 | G13: 0.87 | H13: Calculado: 9,0 x fração de etanol
A14: Etanol anidro | B14: - | C14: 1 | D14: 9 | E14: 0.789 | F14: 0.8 | G14: 0.87 | H14: Valor da spec
A15: E85 | B15: - | C15: - | D15: 9.75 | E15: 0.78 | F15: 0.8 | G15: 0.87 | H15: Valor da spec
A16: Metanol | B16: - | C16: - | D16: 6.42 | E16: 0.792 | F16: 0.65 | G16: 0.7 | H16: Valor da spec (lambda com aviso amarelo)
A18: Conferência: a spec traz E32 = 12,80 e 0,756; E25 = 13,21 e 0,752; EHC = 8,37.

Sheet Conferencia
A1: Conferência dos casos golden (SPEC 7.6) - tolerância de 1%
A3: Item | B3: Esperado A | C3: Calculado A | D3: A | E3: Esperado B | F3: Calculado B | G3: B | H3: Esperado C | I3: Calculado C | J3: C | K3: Esperado D | L3: Calculado D | M3: D
A4: Wa (lb/min) | B4: 57.31 | C4: =Cadeia!C41 | D4: =IF(ISNUMBER(B4),IF(ABS(C4/B4-1)<=0.01,"OK","FALHA"),IF(C4=B4,"OK","FALHA")) | E4: 37.57 | F4: =Cadeia!D41 | G4: =IF(ISNUMBER(E4),IF(ABS(F4/E4-1)<=0.01,"OK","FALHA"),IF(F4=E4,"OK","FALHA")) | H4: 14.09 | I4: =Cadeia!E41 | J4: =IF(ISNUMBER(H4),IF(ABS(I4/H4-1)<=0.01,"OK","FALHA"),IF(I4=H4,"OK","FALHA")) | K4: 42.27 | L4: =Cadeia!F41 | M4: =IF(ISNUMBER(K4),IF(ABS(L4/K4-1)<=0.01,"OK","FALHA"),IF(L4=K4,"OK","FALHA"))
A5: MAP (psia) | B5: 25.89 | C5: =Cadeia!C52 | D5: =IF(ISNUMBER(B5),IF(ABS(C5/B5-1)<=0.01,"OK","FALHA"),IF(C5=B5,"OK","FALHA"))
A6: PR | B6: 2.04 | C6: =Cadeia!C54 | D6: =IF(ISNUMBER(B6),IF(ABS(C6/B6-1)<=0.01,"OK","FALHA"),IF(C6=B6,"OK","FALHA")) | E6: 2.91 | F6: =Cadeia!D54 | G6: =IF(ISNUMBER(E6),IF(ABS(F6/E6-1)<=0.01,"OK","FALHA"),IF(F6=E6,"OK","FALHA")) | H6: 2.78 | I6: =Cadeia!E54 | J6: =IF(ISNUMBER(H6),IF(ABS(I6/H6-1)<=0.01,"OK","FALHA"),IF(I6=H6,"OK","FALHA"))
A7: Combustível (kg/h) | E7: 152.8 | F7: =Cadeia!D43 | G7: =IF(ISNUMBER(E7),IF(ABS(F7/E7-1)<=0.01,"OK","FALHA"),IF(F7=E7,"OK","FALHA")) | H7: 37.5 | I7: =Cadeia!E43 | J7: =IF(ISNUMBER(H7),IF(ABS(I7/H7-1)<=0.01,"OK","FALHA"),IF(I7=H7,"OK","FALHA")) | K7: 103.3 | L7: =Cadeia!F43 | M7: =IF(ISNUMBER(K7),IF(ABS(L7/K7-1)<=0.01,"OK","FALHA"),IF(L7=K7,"OK","FALHA"))
A8: BSFC | H8: 0.558 | I8: =Cadeia!E44 | J8: =IF(ISNUMBER(H8),IF(ABS(I8/H8-1)<=0.01,"OK","FALHA"),IF(I8=H8,"OK","FALHA")) | K8: 0.513 | L8: =Cadeia!F44 | M8: =IF(ISNUMBER(K8),IF(ABS(L8/K8-1)<=0.01,"OK","FALHA"),IF(L8=K8,"OK","FALHA"))
A9: Cilindrada (cc) | H9: 999 | I9: =Cadeia!E45 | J9: =IF(ISNUMBER(H9),IF(ABS(I9/H9-1)<=0.01,"OK","FALHA"),IF(I9=H9,"OK","FALHA")) | K9: 6002 | L9: =Cadeia!F45 | M9: =IF(ISNUMBER(K9),IF(ABS(L9/K9-1)<=0.01,"OK","FALHA"),IF(L9=K9,"OK","FALHA"))
A10: Vazão por bico (g/min) | E10: 796 | F10: =Cadeia!D57 | G10: =IF(ISNUMBER(E10),IF(ABS(F10/E10-1)<=0.01,"OK","FALHA"),IF(F10=E10,"OK","FALHA")) | H10: 260 | I10: =Cadeia!E57 | J10: =IF(ISNUMBER(H10),IF(ABS(I10/H10-1)<=0.01,"OK","FALHA"),IF(I10=H10,"OK","FALHA")) | K10: 179 | L10: =Cadeia!F57 | M10: =IF(ISNUMBER(K10),IF(ABS(L10/K10-1)<=0.01,"OK","FALHA"),IF(L10=K10,"OK","FALHA"))
A11: Vazão por bico (cc/min de combustível) | E11: 984 | F11: =Cadeia!D58 | G11: =IF(ISNUMBER(E11),IF(ABS(F11/E11-1)<=0.01,"OK","FALHA"),IF(F11=E11,"OK","FALHA")) | H11: 344 | I11: =Cadeia!E58 | J11: =IF(ISNUMBER(H11),IF(ABS(I11/H11-1)<=0.01,"OK","FALHA"),IF(I11=H11,"OK","FALHA")) | K11: 237 | L11: =Cadeia!F58 | M11: =IF(ISNUMBER(K11),IF(ABS(L11/K11-1)<=0.01,"OK","FALHA"),IF(L11=K11,"OK","FALHA"))
A12: Vazão nominal (cc/min) | E12: 1058 | F12: =Cadeia!D59 | G12: =IF(ISNUMBER(E12),IF(ABS(F12/E12-1)<=0.01,"OK","FALHA"),IF(F12=E12,"OK","FALHA")) | H12: 358 | I12: =Cadeia!E59 | J12: =IF(ISNUMBER(H12),IF(ABS(I12/H12-1)<=0.01,"OK","FALHA"),IF(I12=H12,"OK","FALHA")) | K12: 247 | L12: =Cadeia!F59 | M12: =IF(ISNUMBER(K12),IF(ABS(L12/K12-1)<=0.01,"OK","FALHA"),IF(L12=K12,"OK","FALHA"))
A13: P_atm (kPa) | E13: 94.3 | F13: =Cadeia!D47 | G13: =IF(ISNUMBER(E13),IF(ABS(F13/E13-1)<=0.01,"OK","FALHA"),IF(F13=E13,"OK","FALHA")) | H13: 94.3 | I13: =Cadeia!E47 | J13: =IF(ISNUMBER(H13),IF(ABS(I13/H13-1)<=0.01,"OK","FALHA"),IF(I13=H13,"OK","FALHA"))
A14: MAP (kPa) | E14: 241 | F14: =Cadeia!D53 | G14: =IF(ISNUMBER(E14),IF(ABS(F14/E14-1)<=0.01,"OK","FALHA"),IF(F14=E14,"OK","FALHA")) | H14: 229 | I14: =Cadeia!E53 | J14: =IF(ISNUMBER(H14),IF(ABS(I14/H14-1)<=0.01,"OK","FALHA"),IF(I14=H14,"OK","FALHA")) | K14: 96.6 | L14: =Cadeia!F53 | M14: =IF(ISNUMBER(K14),IF(ABS(L14/K14-1)<=0.01,"OK","FALHA"),IF(L14=K14,"OK","FALHA"))
A15: T2 (°C) | E15: 173 | F15: =Cadeia!D55 | G15: =IF(ISNUMBER(E15),IF(ABS(F15/E15-1)<=0.01,"OK","FALHA"),IF(F15=E15,"OK","FALHA")) | H15: 165 | I15: =Cadeia!E55 | J15: =IF(ISNUMBER(H15),IF(ABS(I15/H15-1)<=0.01,"OK","FALHA"),IF(I15=H15,"OK","FALHA"))
A16: Tm (°C) | E16: 55 | F16: =Cadeia!D50 | G16: =IF(ISNUMBER(E16),IF(ABS(F16/E16-1)<=0.01,"OK","FALHA"),IF(F16=E16,"OK","FALHA")) | H16: 53 | I16: =Cadeia!E50 | J16: =IF(ISNUMBER(H16),IF(ABS(I16/H16-1)<=0.01,"OK","FALHA"),IF(I16=H16,"OK","FALHA")) | K16: 35 | L16: =Cadeia!F50 | M16: =IF(ISNUMBER(K16),IF(ABS(L16/K16-1)<=0.01,"OK","FALHA"),IF(L16=K16,"OK","FALHA"))
A17: TI efetivo (ms) | E17: 13.81 | F17: =Cadeia!D64 | G17: =IF(ISNUMBER(E17),IF(ABS(F17/E17-1)<=0.01,"OK","FALHA"),IF(F17=E17,"OK","FALHA")) | H17: 14.19 | I17: =Cadeia!E64 | J17: =IF(ISNUMBER(H17),IF(ABS(I17/H17-1)<=0.01,"OK","FALHA"),IF(I17=H17,"OK","FALHA")) | K17: 14.01 | L17: =Cadeia!F64 | M17: =IF(ISNUMBER(K17),IF(ABS(L17/K17-1)<=0.01,"OK","FALHA"),IF(L17=K17,"OK","FALHA"))
A18: TI com tempo morto (ms) | E18: 14.81 | F18: =Cadeia!D65 | G18: =IF(ISNUMBER(E18),IF(ABS(F18/E18-1)<=0.01,"OK","FALHA"),IF(F18=E18,"OK","FALHA")) | H18: 15.19 | I18: =Cadeia!E65 | J18: =IF(ISNUMBER(H18),IF(ABS(I18/H18-1)<=0.01,"OK","FALHA"),IF(I18=H18,"OK","FALHA")) | K18: 15.01 | L18: =Cadeia!F65 | M18: =IF(ISNUMBER(K18),IF(ABS(L18/K18-1)<=0.01,"OK","FALHA"),IF(L18=K18,"OK","FALHA"))
A19: Ciclo (ms) | E19: 17.14 | F19: =Cadeia!D66 | G19: =IF(ISNUMBER(E19),IF(ABS(F19/E19-1)<=0.01,"OK","FALHA"),IF(F19=E19,"OK","FALHA")) | H19: 21.82 | I19: =Cadeia!E66 | J19: =IF(ISNUMBER(H19),IF(ABS(I19/H19-1)<=0.01,"OK","FALHA"),IF(I19=H19,"OK","FALHA")) | K19: 18.46 | L19: =Cadeia!F66 | M19: =IF(ISNUMBER(K19),IF(ABS(L19/K19-1)<=0.01,"OK","FALHA"),IF(L19=K19,"OK","FALHA"))
A20: DC | E20: 0.86 | F20: =Cadeia!D67 | G20: =IF(ISNUMBER(E20),IF(ABS(F20/E20-1)<=0.01,"OK","FALHA"),IF(F20=E20,"OK","FALHA")) | H20: 0.7 | I20: =Cadeia!E67 | J20: =IF(ISNUMBER(H20),IF(ABS(I20/H20-1)<=0.01,"OK","FALHA"),IF(I20=H20,"OK","FALHA")) | K20: 0.81 | L20: =Cadeia!F67 | M20: =IF(ISNUMBER(K20),IF(ABS(L20/K20-1)<=0.01,"OK","FALHA"),IF(L20=K20,"OK","FALHA"))
A21: DC bico 1.300 cc a 3 bar | E21: 0.71 | F21: =Cadeia!D68 | G21: =IF(ISNUMBER(E21),IF(ABS(F21/E21-1)<=0.01,"OK","FALHA"),IF(F21=E21,"OK","FALHA"))
A22: DC bico 1.050 cc a 4 bar | E22: 0.76 | F22: =Cadeia!D69 | G22: =IF(ISNUMBER(E22),IF(ABS(F22/E22-1)<=0.01,"OK","FALHA"),IF(F22=E22,"OK","FALHA"))
A23: BMEP (bar) | E23: 25.2 | F23: =Cadeia!D70 | G23: =IF(ISNUMBER(E23),IF(ABS(F23/E23-1)<=0.01,"OK","FALHA"),IF(F23=E23,"OK","FALHA")) | H23: 24.1 | I23: =Cadeia!E70 | J23: =IF(ISNUMBER(H23),IF(ABS(I23/H23-1)<=0.01,"OK","FALHA"),IF(I23=H23,"OK","FALHA")) | K23: 10.2 | L23: =Cadeia!F70 | M23: =IF(ISNUMBER(K23),IF(ABS(L23/K23-1)<=0.01,"OK","FALHA"),IF(L23=K23,"OK","FALHA"))
A24: Torque (N·m) | E24: 401 | F24: =Cadeia!D71 | G24: =IF(ISNUMBER(E24),IF(ABS(F24/E24-1)<=0.01,"OK","FALHA"),IF(F24=E24,"OK","FALHA")) | H24: 192 | I24: =Cadeia!E71 | J24: =IF(ISNUMBER(H24),IF(ABS(I24/H24-1)<=0.01,"OK","FALHA"),IF(I24=H24,"OK","FALHA")) | K24: 486 | L24: =Cadeia!F71 | M24: =IF(ISNUMBER(K24),IF(ABS(L24/K24-1)<=0.01,"OK","FALHA"),IF(L24=K24,"OK","FALHA"))
A25: Velocidade do pistão (m/s) | E25: 21.7 | F25: =Cadeia!D72 | G25: =IF(ISNUMBER(E25),IF(ABS(F25/E25-1)<=0.01,"OK","FALHA"),IF(F25=E25,"OK","FALHA")) | H25: 14 | I25: =Cadeia!E72 | J25: =IF(ISNUMBER(H25),IF(ABS(I25/H25-1)<=0.01,"OK","FALHA"),IF(I25=H25,"OK","FALHA")) | K25: 17.4 | L25: =Cadeia!F72 | M25: =IF(ISNUMBER(K25),IF(ABS(L25/K25-1)<=0.01,"OK","FALHA"),IF(L25=K25,"OK","FALHA"))
A26: Aspirado: MAP ÷ P_atm a 600 m | K26: 1.024 | L26: =Cadeia!F56 | M26: =IF(ISNUMBER(K26),IF(ABS(L26/K26-1)<=0.01,"OK","FALHA"),IF(L26=K26,"OK","FALHA"))
A27: Aspirado: MAP ÷ P_atm ao nível do mar | K27: 0.953 | L27: =Cadeia!F78 | M27: =IF(ISNUMBER(K27),IF(ABS(L27/K27-1)<=0.01,"OK","FALHA"),IF(L27=K27,"OK","FALHA"))
A28: Semáforo DC | E28: VERMELHO | F28: =Cadeia!D74 | G28: =IF(ISNUMBER(E28),IF(ABS(F28/E28-1)<=0.01,"OK","FALHA"),IF(F28=E28,"OK","FALHA")) | H28: VERDE | I28: =Cadeia!E74 | J28: =IF(ISNUMBER(H28),IF(ABS(I28/H28-1)<=0.01,"OK","FALHA"),IF(I28=H28,"OK","FALHA")) | K28: AMARELO | L28: =Cadeia!F74 | M28: =IF(ISNUMBER(K28),IF(ABS(L28/K28-1)<=0.01,"OK","FALHA"),IF(L28=K28,"OK","FALHA"))
A29: Semáforo BMEP | E29: AMARELO | F29: =Cadeia!D75 | G29: =IF(ISNUMBER(E29),IF(ABS(F29/E29-1)<=0.01,"OK","FALHA"),IF(F29=E29,"OK","FALHA")) | H29: AMARELO | I29: =Cadeia!E75 | J29: =IF(ISNUMBER(H29),IF(ABS(I29/H29-1)<=0.01,"OK","FALHA"),IF(I29=H29,"OK","FALHA")) | K29: VERDE | L29: =Cadeia!F75 | M29: =IF(ISNUMBER(K29),IF(ABS(L29/K29-1)<=0.01,"OK","FALHA"),IF(L29=K29,"OK","FALHA"))
A30: Semáforo pistão | E30: AMARELO | F30: =Cadeia!D76 | G30: =IF(ISNUMBER(E30),IF(ABS(F30/E30-1)<=0.01,"OK","FALHA"),IF(F30=E30,"OK","FALHA")) | H30: VERDE | I30: =Cadeia!E76 | J30: =IF(ISNUMBER(H30),IF(ABS(I30/H30-1)<=0.01,"OK","FALHA"),IF(I30=H30,"OK","FALHA")) | K30: VERDE | L30: =Cadeia!F76 | M30: =IF(ISNUMBER(K30),IF(ABS(L30/K30-1)<=0.01,"OK","FALHA"),IF(L30=K30,"OK","FALHA"))
A31: Semáforo aspirado (600 m) | K31: VERMELHO | L31: =Cadeia!F77 | M31: =IF(ISNUMBER(K31),IF(ABS(L31/K31-1)<=0.01,"OK","FALHA"),IF(L31=K31,"OK","FALHA"))
A33: Resultado | B33: =IF(COUNTIF(B4:M31,"FALHA")=0,"TODOS OK","HÁ FALHAS") | C33: =COUNTIF(B4:M31,"OK")&" OK / "&COUNTIF(B4:M31,"FALHA")&" FALHA"
